<?xml version="1.0" ?>
<robot name="my_robot">
    <link name="base_link">
        <visual>
            <origin xyz=" 0 0 0" rpy="0 0 0" />
            <geometry>
                <box size="0.5 0.3 0.15"/>
            </geometry>
            <material name="metal">
                <color rgba="1 0.4 0 1"/>
            </material>
        </visual>
    </link>

    <joint name="left_wheel_joint" type="continuous">
        <origin xyz="0 0.15 -0.06" rpy="0 0 0"/>
        <parent link="base_link"/>
        <child link="left_wheel_link"/>
        <axis xyz="0 1 0"/>
    </joint>

    <link name="left_wheel_link">
        <visual>
            <origin xyz="0 0 0" rpy="1.5707 0 0" />
            <geometry>
                <cylinder radius="0.08" length = "0.01"/>
            </geometry>
            <material name="wheel">
                <color rgba="0 0 0 1"/>
            </material>
        </visual>
    </link>

    <joint name="right_wheel_joint" type="continuous">
        <origin xyz="0 -0.15 -0.06" rpy="0 0 0"/>
        <parent link="base_link"/>
        <child link="right_wheel_link"/>
        <axis xyz="0 1 0"/>
    </joint>

    <link name="right_wheel_link">
        <visual>
            <origin xyz="0 0 0" rpy="1.5707 0 0" />
            <geometry>
                <cylinder radius="0.08" length = "0.01"/>
            </geometry>
            <material name="wheel">
                <color rgba="0 0 0 1"/>
            </material>
        </visual>
    </link>

    <joint name="front_caster_joint" type="continuous">
        <origin xyz="-0.18 0 -0.08" rpy="0 0 0"/>
        <parent link="base_link"/>
        <child link="front_caster_link"/>
        <axis xyz="0 1 0"/>
    </joint>

    <link name="front_caster_link">
        <visual>
            <origin xyz="0 0 0" rpy="0 0 0"/>
            <geometry>
                <sphere radius="0.04" />
            </geometry>
            <material name="black">
                <color rgba="0 0 0 1"/>
            </material>
        </visual>
    </link>
    
    <joint name="back_caster_joint" type="continuous">
        <origin xyz="0.18 0 -0.08" rpy="0 0 0"/>
        <parent link="base_link"/>
        <child link="back_caster_link"/>
        <axis xyz="0 1 0"/>
    </joint>

    <link name="back_caster_link">
        <visual>
            <origin xyz="0 0 0" rpy="0 0 0"/>
            <geometry>
                <sphere radius="0.04" />
            </geometry>
            <material name="black">
                <color rgba="0 0 0 1"/>
            </material>
        </visual>
    </link>
    
    <link name="kinect_link">
        <visual>
            <origin xyz="0.2 0 0.1" rpy="0 0 1.5707"/>
            <geometry>
                <mesh filename="package://my_robot_description/meshes/kinect.dae" />
            </geometry>
        </visual>
    </link>

    <joint name="kinect_joint" type="fixed">
        <origin xyz="0 0 0" rpy="0 0 0"/>
        <parent link="base_link"/>
        <child link="kinect_link"/>
    </joint>
</robot>
